Workbook

Sheet BL
C2: Consolidated financial Statements of Adidas for 2021-2025
B8: Balance Sheet ( € in millions) | I8: P&L( € in millions) | P8: CF( € in millions)
B10: Years | C10: 2021 | D10: 2022 | E10: 2023 | F10: 2024 | G10: 2025 | I10: Years | J10: 2021 | K10: 2022 | L10: 2023 | M10: 2024 | N10: 2025 | P10: Years | Q10: 2021 | R10: 2022 | S10: 2023 | T10: 2024 | U10: 2025
B12: Assets | P12: Operating activities:
B13: Cash and cash equivalents | C13: =Q44 -> 3828 | D13: =R44 -> 798 | E13: =S44 -> 1431 | F13: =T44 -> 2455 | G13: =U44 -> 1617 | I13: Net sales (Revenue) | J13: 21234 | K13: 22511 | L13: 21427 | M13: 23683 | N13: 24811 | P13: EBT from continuing operations | Q13: =J27 -> 1852 | R13: =K27 -> 388 | S13: =L27 -> 65 | T13: =M27 -> 1121 | U13: =N27 -> 1820
B14: Short-term financial assets | C14: 0 | D14: 0 | E14: 34 | F14: 0 | G14: 0 | I14: COGS | J14: 10469 | K14: 11867 | L14: 11244 | M14: 11658 | N14: 12006 | P14: Depr&Amor&impairmentlosses | Q14: 1149 | R14: 1375 | S14: 1212 | T14: 1208 | U14: 1154
B15: Accounts receivable | C15: 2175 | D15: 2529 | E15: 1906 | F15: 2413 | G15: 2634 | I15: Gross profit | J15: =J13-J14 -> 10765 | K15: =K13-K14 -> 10644 | L15: =L13-L14+1 -> 10184 | M15: =M13-M14+1 -> 12026 | N15: =N13-N14-1 -> 12804 | P15: Other Non-Cash Adjustments | Q15: 36 | R15: 89 | S15: =58-19 -> 39 | T15: -40 | U15: 50
B16: Other current financial assets | C16: 745 | D16: 1014 | E16: 614 | F16: 950 | G16: 518 | I16: Royalty and commission income | J16: 86 | K16: 112 | L16: 83 | M16: 81 | N16: 81 | P16: Net Interest Adjustments | Q16: 98 | R16: 115 | S16: 123 | T16: =164+9 -> 173 | U16: 169
B17: Inventories | C17: 4009 | D17: 5973 | E17: 4525 | F17: 4989 | G17: 5832 | I17: Other operating income | J17: 28 | K17: 173 | L17: 71 | M17: 174 | N17: 41 | P17: Change in Working Capital:
B18: Income tax receivables | C18: 91 | D18: 102 | E18: 156 | F18: 101 | G18: 167 | I18: Marketing and point-of-sale | J18: 2547 | K18: 2763 | L18: 2528 | M18: 2841 | N18: 3079 | P18: Increase in AR&other assets | Q18: -170 | R18: -820 | S18: 996 | T18: -839 | U18: -562
B19: Assets classified as held for sale | C19: 1062 | D19: 1316 | E19: 0 | F19: 0 | G19: 0 | I19: Distribution and selling | J19: 4782 | K19: 5601 | L19: 5547 | M19: 5936 | N19: 5877 | P19: (Increase)/decrease in inventories | Q19: 125 | R19: -1901 | S19: 1280 | T19: -500 | U19: -1104
B20: Other current assets | C20: 2033 | D20: 0 | E20: 1143 | F20: 997 | G20: 1208 | I20: General and administration | J20: 1481 | K20: 1651 | L20: 1839 | M20: 2138 | N20: 1885 | P20: Increase in AP&other liabilities | Q20: 226 | R20: 721 | S20: -857 | T20: 2024 | U20: -377
B21: Total current assets | C21: =SUM(C13:C20) +1 -> 13944 | D21: =SUM(D13:D20) -> 11732 | E21: =SUM(E13:E20) -> 9809 | F21: =SUM(F13:F20)-1 -> 11904 | G21: =SUM(G13:G20) -> 11976 | I21: Other operating expenses | J21: 82 | K21: 245 | L21: 156 | M21: 29 | N21: 30 | P21: Income Taxes Paid | Q21: -444 | R21: -424 | S21: -307 | T21: =-236 -> -236 | U21: -399
I22: EBITDA | J22: =J24+J23 -> 3135 | K22: =K24+K23 -> 2044 | L22: =L24+L23 -> 1480 | M22: =M24+M23 -> 2545 | N22: =N24+N23 -> 3210 | P22: Cash from Discontinued Operations | Q22: 320 | R22: -85 | S22: 0 | T22: 0 | U22: 0
B23: Property, plant, and equipment | C23: 2256 | D23: 2279 | E23: 2157 | F23: 2133 | G23: 1973 | I23: Depreciation&Amortization&impairment losses | J23: =Q14 -> 1149 | K23: =R14 -> 1375 | L23: =S14 -> 1212 | M23: =T14 -> 1208 | N23: =U14 -> 1154 | P23: Net cash (used in)/generated from operating activities | Q23: =SUM(Q13:Q22) -> 3192 | R23: =SUM(R13:R22)-1 -> -543 | S23: =SUM(S13:S22)-1 -> 2550 | T23: =SUM(T13:T22)-1 -> 2910 | U23: =SUM(U13:U22) -> 751
B24: Right-of-use assets | C24: 2569 | D24: 2665 | E24: 2247 | F24: 2779 | G24: 2605 | I24: EBIT(Operating Profit) | J24: =SUM(J15:J17)-SUM(J18:J21)-1 -> 1986 | K24: =SUM(K15:K17)-SUM(K18:K21) -> 669 | L24: =SUM(L15:L17)-SUM(L18:L21) -> 268 | M24: =SUM(M15:M17)-SUM(M18:M21) -> 1337 | N24: =SUM(N15:N17)-SUM(N18:N21)+1 -> 2056
B25: Goodwill | C25: 1228 | D25: 1260 | E25: 1238 | F25: 1275 | G25: 1203 | I25: Financial Income | J25: 19 | K25: 39 | L25: 79 | M25: 101 | N25: 74 | P25: Investing activities:
B26: Trademakrs | C26: 16 | D26: 0 | E26: 0 | F26: 0 | G26: 0 | I26: Financial Expenses | J26: 153 | K26: 320 | L26: 282 | M26: 317 | N26: 310 | P26: CapEx | Q26: -667 | R26: -695 | S26: -504 | T26: -540 | U26: -477
B27: Other intangible assets | C27: 336 | D27: 429 | E27: 442 | F27: 426 | G27: 443 | I27: EBT(Income Before Taxes) | J27: =J24+J25-J26 -> 1852 | K27: =K24+K25-K26 -> 388 | L27: =L24+L25-L26 -> 65 | M27: =M24+M25-M26 -> 1121 | N27: =N24+N25-N26 -> 1820 | P27: Proceeds From Disposals | Q27: 2 | R27: 2 | S27: 10 | T27: 49 | U27: 4
B28: Long-term financial assets | C28: 290 | D28: 301 | E28: 301 | F28: 340 | G28: 353 | I28: Income Taxes | J28: 360 | K28: 134 | L28: 124 | M28: 297 | N28: 443 | P28: Proceeds from disposal of discont opers | Q28: 177 | R28: 1165 | S28: -19 | T28: 100 | U28: 100
B29: Other non-current financial assets | C29: 160 | D29: 336 | E29: 418 | F29: 234 | G29: 217 | I29: Net Income (Cont Opers) | J29: =J27-J28 -> 1492 | K29: =K27-K28 -> 254 | L29: =L27-L28+1 -> -58 | M29: =M27-M28 -> 824 | N29: =N27-N28 -> 1377 | P29: Other Investing Activities | Q29: 64 | R29: 23 | S29: 62 | T29: 35 | U29: -31
B30: Deferred tax assets | C30: 1263 | D30: 1216 | E30: 1358 | F30: 1272 | G30: 1077 | I30: Gain/(loss) from discontinued operations, net of tax | J30: 666 | K30: 384 | L30: 44 | M30: 8 | N30: 8 | P30: Net cash generated from/(used in) investing activitie | Q30: =SUM(Q26:Q29) -> -424 | R30: =SUM(R26:R29) -> 495 | S30: =SUM(S26:S29) -> -451 | T30: =SUM(T26:T29) -> -356 | U30: =SUM(U26:U29) -> -404
B31: Other non-current assets | C31: 74 | D31: 76 | E31: 49 | F31: 291 | G31: 415 | I31: Net Income | J31: =J29+J30 -> 2158 | K31: =K29+K30 -> 638 | L31: =L29+L30 -> -14 | M31: =M29+M30 -> 832 | N31: =N29+N30 -> 1385
B32: Total non-current assets | C32: =SUM(C23:C31)+1 -> 8193 | D32: =SUM(D23:D31)+1 -> 8563 | E32: =SUM(E23:E31)+1 -> 8211 | F32: =SUM(F23:F31)+1 -> 8751 | G32: =SUM(G23:G31) -> 8286 | P32: Financing activities:
P33: Net Borrowings | Q33: -679 | R33: 976 | S33: -497 | T33: -497 | U33: 164
B34: Total Assets | C34: =C21+C32 -> 22137 | D34: =D21+D32+1 -> 20296 | E34: =E21+E32 -> 18020 | F34: =F21+F32 -> 20655 | G34: =G21+G32 -> 20262 | P34: Repayment of Lease liabilities | Q34: -572 | R34: -631 | S34: -603 | T34: -656 | U34: -643
P35: Dividends paid | Q35: -585 | R35: -632 | S35: -158 | T35: -165 | U35: -399
B36: Liabilities | P36: Share BuyBack | Q36: -1005 | R36: -2505 | S36: -4 | T36: -11 | U36: -4
B37: Short-term borrowings | C37: 29 | D37: 527 | E37: 549 | F37: 570 | G37: 645 | P37: Other Financial Activities | Q37: -150 | R37: -171 | S37: -163 | T37: -230 | U37: -221
B38: Accounts payable | C38: 2294 | D38: 2908 | E38: 2276 | F38: 3096 | G38: 2910 | P38: Net cash used in financing activities | Q38: =SUM(Q33:Q37) -> -2991 | R38: =SUM(R33:R37) -> -2963 | S38: =SUM(S33:S37) -> -1425 | T38: =SUM(T33:T37) -> -1559 | U38: =SUM(U33:U37) -> -1103
B39: Current lease liabilities | C39: 573 | D39: 643 | E39: 545 | F39: 607 | G39: 603
B40: Other current financial liabilities | C40: 363 | D40: 424 | E40: 266 | F40: 191 | G40: 336 | P40: Sum of Cash Flows | Q40: =Q23+Q30+Q38 -> -223 | R40: =R23+R30+R38 -> -3011 | S40: =S23+S30+S38 -> 674 | T40: =T23+T30+T38 -> 995 | U40: =U23+U30+U38 -> -756
B41: Income taxes | C41: 536 | D41: 302 | E41: 323 | F41: 334 | G41: 357 | P41: Effect of exchange rates on cash | Q41: 57 | R41: -19 | S41: -41 | T41: 29 | U41: -82
B42: Other current provisions | C42: 1458 | D42: 1589 | E42: 1323 | F42: 1538 | G42: 1208 | P42: Net change in Cash | Q42: =Q40+Q41 -> -166 | R42: =R40+R41 -> -3030 | S42: =S40+S41 -> 633 | T42: =T40+T41 -> 1024 | U42: =U40+U41 -> -838
B43: Current accrued liabilities | C43: 2684 | D43: 2412 | E43: 2273 | F43: 2659 | G43: 2383 | P43: Cash&cash equivalents at beg of year | Q43: 3994 | R43: =Q44 -> 3828 | S43: =R44 -> 798 | T43: =S44 -> 1431 | U43: =T44 -> 2455
B44: Other current liabilities | C44: 434 | D44: 452 | E44: 488 | F44: 598 | G44: 652 | P44: Cash&cash equivalents at end of period | Q44: =SUM(Q42:Q43) -> 3828 | R44: =SUM(R42:R43) -> 798 | S44: =SUM(S42:S43) -> 1431 | T44: =SUM(T42:T43) -> 2455 | U44: =SUM(U42:U43) -> 1617
B45: Liabilities classified as held for sale | C45: 594 | D45: 0 | E45: 0 | F45: 0 | G45: 0
B46: Total current liabilities | C46: =SUM(C37:C45) -> 8965 | D46: =SUM(D37:D45) -> 9257 | E46: =SUM(E37:E45) -> 8043 | F46: =SUM(F37:F45) -> 9593 | G46: =SUM(G37:G45) -> 9094
B48: Long-term borrowings | C48: 2466 | D48: 2946 | E48: 2430 | F48: 1915 | G48: 1996
B49: Non-current lease liabilities | C49: 2263 | D49: 2343 | E49: 2039 | F49: 2495 | G49: 2310
...

Sheet Ratio Analysis
B2: Years | C2: =BL!C10 -> 2021 | D2: =BL!D10 -> 2022 | E2: =BL!E10 -> 2023 | F2: =BL!F10 -> 2024 | G2: =BL!G10 -> 2025 | I2: Mean | J2: Median
B4: Sales Growth | D4: =(BL!K13/BL!J13)-1 -> 0.060139399 | E4: =(BL!L13/BL!K13)-1 -> -0.048154236 | F4: =(BL!M13/BL!L13)-1 -> 0.10528772 | G4: =(BL!N13/BL!M13)-1 -> 0.047629101 | I4: =AVERAGE(D4:G4) -> 0.041225496 | J4: =MEDIAN(D4:G4) -> 0.05388425
B5: EBITDA Growth | D5: =(BL!K22/BL!J22) -1 -> -0.34800638 | E5: =(BL!L22/BL!K22) -1 -> -0.27592955 | F5: =(BL!M22/BL!L22) -1 -> 0.71959459 | G5: =(BL!N22/BL!M22) -1 -> 0.26129666 | I5: =AVERAGE(D5:G5) -> 0.089238831 | J5: =MEDIAN(D5:G5) -> -0.0073164449
B6: EBIT Growth | D6: =BL!K24/BL!J24 - 1 -> -0.66314199 | E6: =BL!L24/BL!K24 - 1 -> -0.59940209 | F6: =BL!M24/BL!L24 - 1 -> 3.988806 | G6: =BL!N24/BL!M24 - 1 -> 0.53777113 | I6: =AVERAGE(D6:G6) -> 0.81600825 | J6: =MEDIAN(D6:G6) -> -0.030815482
B7: EBT Growth | D7: =BL!K27/BL!J27 - 1 -> -0.79049676 | E7: =BL!L27/BL!K27 - 1 -> -0.83247423 | F7: =BL!M27/BL!L27 - 1 -> 16.246154 | G7: =BL!N27/BL!M27 - 1 -> 0.6235504 | I7: =AVERAGE(D7:G7) -> 3.8116833 | J7: =MEDIAN(D7:G7) -> -0.083473179
B8: Net Profit Growth (Cont Opers) | D8: =BL!K29/BL!J29 - 1 -> -0.82975871 | E8: =BL!L29/BL!K29 - 1 -> -1.2283465 | F8: =BL!M29/BL!L29 - 1 -> -15.206897 | G8: =BL!N29/BL!M29 - 1 -> 0.6711165 | I8: =AVERAGE(D8:G8) -> -4.1484713 | J8: =MEDIAN(D8:G8) -> -1.0290526
B9: Dividens Paid | D9: =BL!R35/BL!Q35 - 1 -> 0.08034188 | E9: =BL!S35/BL!R35 - 1 -> -0.75 | F9: =BL!T35/BL!S35 - 1 -> 0.044303797 | G9: =BL!U35/BL!T35 - 1 -> 1.4181818 | I9: =AVERAGE(D9:G9) -> 0.19820687 | J9: =MEDIAN(D9:G9) -> 0.062322839
B11: Gross Profit Margin | C11: =BL!J15/BL!J13 -> 0.50696995 | D11: =BL!K15/BL!K13 -> 0.4728355 | E11: =BL!L15/BL!L13 -> 0.47528819 | F11: =BL!M15/BL!M13 -> 0.5077904 | G11: =BL!N15/BL!N13 -> 0.51606142 | I11: =AVERAGE(C11:G11) -> 0.49578909 | J11: =MEDIAN(C11:G11) -> 0.50696995
B12: EBITDA Margin | C12: =BL!J22/BL!J13 -> 0.14764058 | D12: =BL!K22/BL!K13 -> 0.090800053 | E12: =BL!L22/BL!L13 -> 0.069071732 | F12: =BL!M22/BL!M13 -> 0.10746105 | G12: =BL!N22/BL!N13 -> 0.1293781 | I12: =AVERAGE(C12:G12) -> 0.1088703 | J12: =MEDIAN(C12:G12) -> 0.10746105
B13: EBIT Margin | C13: =BL!J24/BL!J13 -> 0.093529246 | D13: =BL!K24/BL!K13 -> 0.029718804 | E13: =BL!L24/BL!L13 -> 0.012507584 | F13: =BL!M24/BL!M13 -> 0.056453997 | G13: =BL!N24/BL!N13 -> 0.082866471 | I13: =AVERAGE(C13:G13) -> 0.05501522 | J13: =MEDIAN(C13:G13) -> 0.056453997
B14: EBT Margin | C14: =BL!J24/BL!J13 -> 0.093529246 | D14: =BL!K24/BL!K13 -> 0.029718804 | E14: =BL!L24/BL!L13 -> 0.012507584 | F14: =BL!M24/BL!M13 -> 0.056453997 | G14: =BL!N24/BL!N13 -> 0.082866471 | I14: =AVERAGE(C14:G14) -> 0.05501522 | J14: =MEDIAN(C14:G14) -> 0.056453997
B15: Net Profit Margin (Cont Opers) | C15: =BL!J29/BL!J13 -> 0.07026467 | D15: =BL!K29/BL!K13 -> 0.011283373 | E15: =BL!L29/BL!L13 -> -0.0027068652 | F15: =BL!M29/BL!M13 -> 0.034792889 | G15: =BL!N29/BL!N13 -> 0.055499577 | I15: =AVERAGE(C15:G15) -> 0.033826729 | J15: =MEDIAN(C15:G15) -> 0.034792889
B17: COGS%Sales | C17: =BL!J14/BL!J13 -> 0.49303005 | D17: =BL!K14/BL!K13 -> 0.5271645 | E17: =BL!L14/BL!L13 -> 0.52475848 | F17: =BL!M14/BL!M13 -> 0.49225183 | G17: =BL!N14/BL!N13 -> 0.48389827 | I17: =AVERAGE(C17:G17) -> 0.50422062 | J17: =MEDIAN(C17:G17) -> 0.49303005
B18: OperEx%Sales | C18: =SUM(BL!J18:J21)/BL!J13 -> 0.41876236 | D18: =SUM(BL!K18:K21)/BL!K13 -> 0.45577718 | E18: =SUM(BL!L18:L21)/BL!L13 -> 0.4699678 | F18: =SUM(BL!M18:M21)/BL!M13 -> 0.46210362 | G18: =SUM(BL!N18:N21)/BL!N13 -> 0.43815243 | I18: =AVERAGE(C18:G18) -> 0.44895268 | J18: =MEDIAN(C18:G18) -> 0.45577718
B19: OpenIncome%Sales | C19: =C13 -> 0.093529246 | D19: =D13 -> 0.029718804 | E19: =E13 -> 0.012507584 | F19: =F13 -> 0.056453997 | G19: =G13 -> 0.082866471 | I19: =AVERAGE(C19:G19) -> 0.05501522 | J19: =MEDIAN(C19:G19) -> 0.056453997
B21: Return on Capital Employed | C21: =BL!J24/(BL!C34-BL!C46) -> 0.15077437 | D21: =BL!K24/(BL!D34-BL!D46) -> 0.060603316 | E21: =BL!L24/(BL!E34-BL!E46) -> 0.026861782 | F21: =BL!M24/(BL!F34-BL!F46) -> 0.12086422 | G21: =BL!N24/(BL!G34-BL!G46) -> 0.18409742 | I21: =AVERAGE(C21:G21) -> 0.10864022 | J21: =MEDIAN(C21:G21) -> 0.12086422
B22: Retention Ratio | C22: =(ABS(BL!J31)-ABS(BL!Q35))/BL!J31 -> 0.72891566 | D22: =IF(BL!K31<=0,0,(ABS(BL!K31)-ABS(BL!R35))/BL!K31) -> 0.0094043887 | E22: =IF(BL!L31<=0,0,(ABS(BL!L31)-ABS(BL!S35))/BL!L31) -> 0 | F22: =IF(BL!M31<=0,0,(ABS(BL!M31)-ABS(BL!T35))/BL!M31) -> 0.80168269 | G22: =IF(BL!N31<=0,0,(ABS(BL!N31)-ABS(BL!U35))/BL!N31) -> 0.71191336 | I22: =AVERAGE(C22:G22) -> 0.45038322 | J22: =MEDIAN(C22:G22) -> 0.71191336
B23: ROE | C23: =DuPont!D19 -> 0.21202217 | D23: =DuPont!E19 -> 0.040601023 | E23: =DuPont!F19 -> -0.012117414 | F23: =DuPont!G19 -> 0.16386596 | G23: =DuPont!H19 -> 0.24475649 | I23: =AVERAGE(C23:G23) -> 0.12982565 | J23: =MEDIAN(C23:G23) -> 0.16386596
B24: Self Sustained Growth Rate | C24: =C22*C23 -> 0.15454628 | D24: =D22*D23 -> 0.0003818278 | E24: =E22*E23 -> 0 | F24: =F22*F23 -> 0.13136851 | G24: =G22*G23 -> 0.17424541 | I24: =AVERAGE(C24:G24) -> 0.092108405 | J24: =MEDIAN(C24:G24) -> 0.13136851
B25: Interest Coverge | C25: =BL!J24/BL!J26 -> 12.980392 | D25: =BL!K24/BL!K26 -> 2.090625 | E25: =BL!L24/BL!L26 -> 0.95035461 | F25: =BL!M24/BL!M26 -> 4.2176656 | G25: =BL!N24/BL!N26 -> 6.6322581 | I25: =AVERAGE(C25:G25) -> 5.3742591 | J25: =MEDIAN(C25:G25) -> 4.2176656
B27: AR Turnover Ratio | C27: =BL!J13/((1952+BL!C15)/2) -> 10.290283 | D27: =BL!K13/((BL!C15+BL!D15)/2) -> 9.5710034 | E27: =BL!L13/((BL!D15+BL!E15)/2) -> 9.6626832 | F27: =BL!M13/((BL!E15+BL!F15)/2) -> 10.96689 | G27: =BL!N13/((BL!F15+BL!G15)/2) -> 9.8319794 | I27: =AVERAGE(C27:G27) -> 10.064568 | J27: =MEDIAN(C27:G27) -> 9.8319794
B28: AP Turnover Ratio | C28: =BL!J14/((2390+BL!C38)/2) -> 4.470111 | D28: =BL!K14/((BL!C38+BL!D38)/2) -> 4.562476 | E28: =BL!L14/((BL!D38+BL!E38)/2) -> 4.337963 | F28: =BL!M14/((BL!E38+BL!F38)/2) -> 4.3402829 | G28: =BL!N14/((BL!F38+BL!G38)/2) -> 3.998002 | I28: =AVERAGE(C28:G28) -> 4.341767 | J28: =MEDIAN(C28:G28) -> 4.3402829
B29: Inventory Ratio | C29: =BL!J14/((4397+BL!C17)/2) -> 2.4908399 | D29: =BL!K14/((BL!C17+BL!D17)/2) -> 2.3776798 | E29: =BL!L14/((BL!D17+BL!E17)/2) -> 2.1421223 | F29: =BL!M14/((BL!E17+BL!F17)/2) -> 2.4507042 | G29: =BL!N14/((BL!F17+BL!G17)/2) -> 2.2190186 | I29: =AVERAGE(C29:G29) -> 2.336073 | J29: =MEDIAN(C29:G29) -> 2.3776798
B30: Fixed assets Ratio | C30: =BL!J13/((4839+BL!C23+BL!C24+BL!C27)/2) -> 4.2468 | D30: =BL!K13/((BL!C23+BL!C24+BL!C27+BL!D23+BL!D24+BL!D27)/2) -> 4.27397 | E30: =BL!L13/((BL!D23+BL!D24+BL!D27+BL!E23+BL!E24+BL!E27)/2) -> 4.193561 | F30: =BL!M13/((BL!E23+BL!E24+BL!E27+BL!F23+BL!F24+BL!F27)/2) -> 4.6510212 | G30: =BL!N13/((BL!F23+BL!F24+BL!F27+BL!G23+BL!G24+BL!G27)/2) -> 4.7902307 | I30: =AVERAGE(C30:G30) -> 4.4311166 | J30: =MEDIAN(C30:G30) -> 4.27397
B31: Capital Turnover Ratio | C31: =BL!J13/(BL!C34-BL!C46) -> 1.6120559 | D31: =BL!K13/(BL!D34-BL!D46) -> 2.0392246 | E31: =BL!L13/(BL!E34-BL!E46) -> 2.1476396 | F31: =BL!M13/(BL!F34-BL!F46) -> 2.1409329 | G31: =BL!N13/(BL!G34-BL!G46) -> 2.2216153 | I31: =AVERAGE(C31:G31) -> 2.0322937 | J31: =MEDIAN(C31:G31) -> 2.1409329
B33: DSO | C33: =365/C27 -> 35.470354 | D33: =365/D27 -> 38.136022 | E33: =365/E27 -> 37.774187 | F33: =365/F27 -> 33.281996 | G33: =365/G27 -> 37.123756 | I33: =AVERAGE(C33:G33) -> 36.357263 | J33: =MEDIAN(C33:G33) -> 37.123756
B34: DPO | C34: =365/C28 -> 81.653453 | D34: =365/D28 -> 80.000421 | E34: =365/E28 -> 84.140875 | F34: =365/F28 -> 84.0959 | G34: =365/G28 -> 91.295602 | I34: =AVERAGE(C34:G34) -> 84.23725 | J34: =MEDIAN(C34:G34) -> 84.0959
B35: DIO | C35: =365/C29 -> 146.53692 | D35: =365/D29 -> 153.511 | E35: =365/E29 -> 170.39176 | F35: =365/F29 -> 148.93678 | G35: =365/G29 -> 164.48713 | I35: =AVERAGE(C35:G35) -> 156.77272 | J35: =MEDIAN(C35:G35) -> 153.511
B36: Cash Conversion Cycle | C36: =C33+C35-C34 -> 100.35382 | D36: =D33+D35-D34 -> 111.6466 | E36: =E33+E35-E34 -> 124.02508 | F36: =F33+F35-F34 -> 98.122877 | G36: =G33+G35-G34 -> 110.31528 | I36: =AVERAGE(C36:G36) -> 108.89273 | J36: =MEDIAN(C36:G36) -> 110.31528
B38: OCF/Sales | C38: =BL!Q23/BL!J13 -> 0.15032495 | D38: =BL!R23/BL!K13 -> -0.024121541 | E38: =BL!S23/BL!L13 -> 0.11900873 | F38: =BL!T23/BL!M13 -> 0.12287295 | G38: =BL!U23/BL!N13 -> 0.030268832 | I38: =AVERAGE(C38:G38) -> 0.079670783 | J38: =MEDIAN(C38:G38) -> 0.11900873
B39: OCF/Total Assets | C39: =BL!Q23/(AVERAGE(BL!C34,21053)) -> 0.14781199 | D39: =BL!R23/(AVERAGE(BL!C34:D34)) -> -0.025593288 | E39: =BL!S23/(AVERAGE(BL!D34:E34)) -> 0.13310366 | F39: =BL!T23/(AVERAGE(BL!E34:F34)) -> 0.15048481 | G39: =BL!U23/(AVERAGE(BL!F34:G34)) -> 0.036708459 | I39: =AVERAGE(C39:G39) -> 0.088503127 | J39: =MEDIAN(C39:G39) -> 0.13310366
B40: OCF/Total Debt | C40: =BL!Q30/((5890+BL!C37+BL!C39+BL!C48+BL!C49)/2) -> -0.075572587 | D40: =BL!Q23/((BL!C37+BL!C39+BL!C48+BL!C49+BL!D37+BL!D39+BL!D48+BL!D49)/2) -> 0.54147583 | E40: =BL!R23/((BL!D37+BL!D39+BL!D48+BL!D49+BL!E37+BL!E39+BL!E48+BL!E49)/2) -> -0.090334387 | F40: =BL!S23/((BL!E37+BL!E39+BL!E48+BL!E49+BL!F37+BL!F39+BL!F48+BL!F49)/2) -> 0.4573991 | G40: =BL!T23/((BL!F37+BL!F39+BL!F48+BL!F49+BL!G37+BL!G39+BL!G48+BL!G49)/2) -> 0.52239476 | I40: =AVERAGE(C40:G40) -> 0.27107254 | J40: =MEDIAN(C40:G40) -> 0.4573991

Sheet DuPont
C2: Adidas DuPoint Analysis
R6: Financial Summary
B7: About the Company
B8: Founded on performance, adidas sporting goods equipment supports athletes at all levels. Men, women and kids will find their best form in sneakers and activewear made to perform under pressure. adidas sportswear breathes, manages sweat and helps support working muscles.
B13: DuPont Analysis - Return on Equity & Return on Asset
B15: Return on Equity
C16: 2020 | D16: 2021 | E16: 2022 | F16: 2023 | G16: 2024 | H16: 2025
B17: Net Income | C17: 461 | D17: =BL!J29 -> 1492 | E17: =BL!K29 -> 254 | F17: =BL!L29 -> -58 | G17: =BL!M29 -> 824 | H17: =BL!N29 -> 1377
B18: Avg Shareholders Equity(not 2020) | C18: 6554 | D18: =(C18+BL!C62)/2 -> 7037 | E18: =(BL!C62+BL!D62)/2 -> 6256 | F18: =(BL!D62+BL!E62)/2 -> 4786.5 | G18: =(BL!E62+BL!F62)/2 -> 5028.5 | H18: =(BL!F62+BL!G62)/2 -> 5626
B19: ROE | D19: =D17/D18 -> 0.21202217 | E19: =E17/E18 -> 0.040601023 | F19: =F17/F18 -> -0.012117414 | G19: =G17/G18 -> 0.16386596 | H19: =H17/H18 -> 0.24475649
B21: Return on Equity (DuPont Analysis0
C22: 2020 | D22: 2021 | E22: 2022 | F22: 2023 | G22: 2024 | H22: 2025
B23: Net Income | C23: =C17 -> 461 | D23: =D17 -> 1492 | E23: =E17 -> 254 | F23: =F17 -> -58 | G23: =G17 -> 824 | H23: =H17 -> 1377
B24: Revenue | D24: =BL!J13 -> 21234 | E24: =BL!K13 -> 22511 | F24: =BL!L13 -> 21427 | G24: =BL!M13 -> 23683 | H24: =BL!N13 -> 24811
B25: Net Profit Margin | D25: =D23/D24 -> 0.07026467 | E25: =E23/E24 -> 0.011283373 | F25: =F23/F24 -> -0.0027068652 | G25: =G23/G24 -> 0.034792889 | H25: =H23/H24 -> 0.055499577
B27: Revenue | D27: =D24 -> 21234 | E27: =E24 -> 22511 | F27: =F24 -> 21427 | G27: =G24 -> 23683 | H27: =H24 -> 24811
B28: Avg Total Assets(not 2020) | C28: 21053 | D28: =(C28+BL!C34)/2 -> 21595 | E28: =(BL!C34+BL!D34)/2 -> 21216.5 | F28: =(BL!D34+BL!E34)/2 -> 19158 | G28: =(BL!E34+BL!F34)/2 -> 19337.5 | H28: =(BL!F34+BL!G34)/2 -> 20458.5
B29: Asset Turnover Ratio | D29: =D27/D28 -> 0.98328317 | E29: =E27/E28 -> 1.0610138 | F29: =F27/F28 -> 1.1184362 | G29: =G27/G28 -> 1.2247188 | H29: =H27/H28 -> 1.2127478
B31: Avg Total Assets(not 2020) | D31: =D28 -> 21595 | E31: =E28 -> 21216.5 | F31: =F28 -> 19158 | G31: =G28 -> 19337.5 | H31: =H28 -> 20458.5
B32: Avg Shareholders Equity | D32: =D18 -> 7037 | E32: =E18 -> 6256 | F32: =F18 -> 4786.5 | G32: =G18 -> 5028.5 | H32: =H18 -> 5626
B33: Financial Leverage Ratio | D33: =D31/D32 -> 3.0687793 | E33: =E31/E32 -> 3.3913843 | F33: =F31/F32 -> 4.0025071 | G33: =G31/G32 -> 3.8455802 | H33: =H31/H32 -> 3.6364202
B35: ROE | D35: =D25*D29*D33 -> 0.21202217 | E35: =E25*E29*E33 -> 0.040601023 | F35: =F25*F29*F33 -> -0.012117414 | G35: =G25*G29*G33 -> 0.16386596 | H35: =H25*H29*H33 -> 0.24475649
B37: Return on Asset
C38: 2020 | D38: 2021 | E38: 2022 | F38: 2023 | G38: 2024 | H38: 2025
B39: Net Income | C39: =C17 -> 461 | D39: =D17 -> 1492 | E39: =E17 -> 254 | F39: =F17 -> -58 | G39: =G17 -> 824 | H39: =H17 -> 1377
B40: Avg Total Assets(not 2020) | C40: =C28 -> 21053 | D40: =D28 -> 21595 | E40: =E28 -> 21216.5 | F40: =F28 -> 19158 | G40: =G28 -> 19337.5 | H40: =H28 -> 20458.5
B41: ROA | D41: =D39/D40 -> 0.069090067 | E41: =E39/E40 -> 0.011971814 | F41: =F39/F40 -> -0.0030274559 | G41: =G39/G40 -> 0.042611506 | H41: =H39/H40 -> 0.067306987
B43: Return on Asset(DuPont Analysis)
C44: 2020 | D44: 2021 | E44: 2022 | F44: 2023 | G44: 2024 | H44: 2025
B45: Net Income | D45: =D23 -> 1492 | E45: =E23 -> 254 | F45: =F23 -> -58 | G45: =G23 -> 824 | H45: =H23 -> 1377
B46: Revenue | D46: =D24 -> 21234 | E46: =E24 -> 22511 | F46: =F24 -> 21427 | G46: =G24 -> 23683 | H46: =H24 -> 24811
B47: Net Profit Margin | D47: =D45/D46 -> 0.07026467 | E47: =E45/E46 -> 0.011283373 | F47: =F45/F46 -> -0.0027068652 | G47: =G45/G46 -> 0.034792889 | H47: =H45/H46 -> 0.055499577
B49: Revenue | D49: =D46 -> 21234 | E49: =E46 -> 22511 | F49: =F46 -> 21427 | G49: =G46 -> 23683 | H49: =H46 -> 24811
B50: Avg Total Assets(not 2020) | D50: =D40 -> 21595 | E50: =E40 -> 21216.5 | F50: =F40 -> 19158 | G50: =G40 -> 19337.5 | H50: =H40 -> 20458.5
B51: Asset Turnover Ratio | D51: =D49/D50 -> 0.98328317 | E51: =E49/E50 -> 1.0610138 | F51: =F49/F50 -> 1.1184362 | G51: =G49/G50 -> 1.2247188 | H51: =H49/H50 -> 1.2127478
B53: ROA | D53: =D47*D51 -> 0.069090067 | E53: =E47*E51 -> 0.011971814 | F53: =F47*F51 -> -0.0030274559 | G53: =G47*G51 -> 0.042611506 | H53: =H47*H51 -> 0.067306987

Sheet Comps Data
B2: Adidas | F2: Nike | J2: Puma | N2: Under Armour | R2: ASICS | V2: STOXX 600 | Z2: S&P 500 | AD2: Nikkei 225
B3: {=_xlfn.STOCKHISTORY("XETR:ADS", "02.04.2024", "02.04.2026", 1, 1)} -> Дата | C3: Закрытие | D3: Return | F3: {=_xlfn.STOCKHISTORY("NKE", "02.04.2024", "02.04.2026", 1, 1)} -> Дата | G3: Закрытие | H3: Return | J3: {=_xlfn.STOCKHISTORY("XETR:PUM", "02.04.2024", "02.04.2026", 1, 1)} -> Дата | K3: Закрытие | L3: Return | N3: {=_xlfn.STOCKHISTORY("UAA", "02.04.2024", "02.04.2026", 1, 1)} -> Дата | O3: Закрытие | P3: Return | R3: {=_xlfn.STOCKHISTORY("ASCCY", DATE(2024, 4, 2), DATE(2026, 4, 2), 1, 1)} -> Дата | S3: Закрытие | T3: Return | V3: {=_xlfn.STOCKHISTORY("XETR:EXSA", DATE(2024,4,2), DATE(2026,4,2), 1, 1)} -> Дата | W3: Закрытие | X3: Return | Z3: {=_xlfn.STOCKHISTORY("VOO", DATE(2024, 4, 2), DATE(2026, 4, 2), 1, 1)} -> Дата | AA3: Закрытие | AB3: Return | AD3: {=_xlfn.STOCKHISTORY("^N225", DATE(2024, 4, 2), DATE(2026, 4, 2), 1, 1)} -> Дата | AE3: Закрытие | AF3: Return
B4: 45384 | C4: 201.6 | F4: 45384 | G4: 82.69 | J4: 45384 | K4: 42.14 | N4: 45383 | O4: 6.82 | R4: 45383 | S4: 11.62 | V4: 45384 | W4: 50.17 | Z4: 45383 | AA4: 476.49 | AD4: 45383 | AE4: 38992.08
B5: 45390 | C5: 196.4 | D5: =(C5/C4) -1 -> -0.025793651 | F5: 45390 | G5: 86.98 | H5: =(G5/G4)-1 -> 0.051880518 | J5: 45390 | K5: 40.39 | L5: =(K5/K4)-1 -> -0.041528239 | N5: 45390 | O5: 6.56 | P5: =(O5/O4)-1 -> -0.038123167 | R5: 45390 | S5: 11.4713 | T5: =(S5/S4)-1 -> -0.012796902 | V5: 45390 | W5: 50.15 | X5: =(W5/W4)-1 -> -0.00039864461 | Z5: 45390 | AA5: 469.57 | AB5: =(AA5/AA4)-1 -> -0.014522865 | AD5: 45390 | AE5: 39523.55 | AF5: =(AE5/AE4)-1 -> 0.013630204
B6: 45397 | C6: 224.6 | D6: =(C6/C5) -1 -> 0.14358452 | F6: 45397 | G6: 89.9 | H6: =(G6/G5)-1 -> 0.033570936 | J6: 45397 | K6: 42.56 | L6: =(K6/K5)-1 -> 0.05372617 | N6: 45397 | O6: 6.73 | P6: =(O6/O5)-1 -> 0.025914634 | R6: 45397 | S6: 10.76 | T6: =(S6/S5)-1 -> -0.062006922 | V6: 45397 | W6: 49.55 | X6: =(W6/W5)-1 -> -0.011964108 | Z6: 45397 | AA6: 455.1 | AB6: =(AA6/AA5)-1 -> -0.030815427 | AD6: 45397 | AE6: 37068.35 | AF6: =(AE6/AE5)-1 -> -0.062119926
B7: 45404 | C7: 230.9 | D7: =(C7/C6) -1 -> 0.028049866 | F7: 45404 | G7: 88.46 | H7: =(G7/G6)-1 -> -0.016017798 | J7: 45404 | K7: 43.71 | L7: =(K7/K6)-1 -> 0.027020677 | N7: 45404 | O7: 6.8 | P7: =(O7/O6)-1 -> 0.010401189 | R7: 45404 | S7: 10.785 | T7: =(S7/S6)-1 -> 0.0023234201 | V7: 45404 | W7: 50.58 | X7: =(W7/W6)-1 -> 0.020787084 | Z7: 45404 | AA7: 467.21 | AB7: =(AA7/AA6)-1 -> 0.026609536 | AD7: 45404 | AE7: 37934.76 | AF7: =(AE7/AE6)-1 -> 0.023373309
B8: 45411 | C8: 225 | D8: =(C8/C7) -1 -> -0.025552187 | F8: 45411 | G8: 85.4 | H8: =(G8/G7)-1 -> -0.034591906 | J8: 45411 | K8: 44.77 | L8: =(K8/K7)-1 -> 0.024250744 | N8: 45411 | O8: 6.74 | P8: =(O8/O7)-1 -> -0.0088235294 | R8: 45411 | S8: 11.0025 | T8: =(S8/S7)-1 -> 0.020166898 | V8: 45411 | W8: 50.48 | X8: =(W8/W7)-1 -> -0.001977066 | Z8: 45411 | AA8: 469.98 | AB8: =(AA8/AA7)-1 -> 0.0059288115 | AD8: 45412 | AE8: 38236.07 | AF8: =(AE8/AE7)-1 -> 0.0079428471
B9: 45418 | C9: 224.4 | D9: =(C9/C8) -1 -> -0.0026666667 | F9: 45418 | G9: 85.39 | H9: =(G9/G8)-1 -> -0.00011709602 | J9: 45418 | K9: 50.82 | L9: =(K9/K8)-1 -> 0.13513514 | N9: 45418 | O9: 6.71 | P9: =(O9/O8)-1 -> -0.0044510386 | R9: 45418 | S9: 13.125 | T9: =(S9/S8)-1 -> 0.1929107 | V9: 45418 | W9: 52.13 | X9: =(W9/W8)-1 -> 0.032686212 | Z9: 45418 | AA9: 478.74 | AB9: =(AA9/AA8)-1 -> 0.018639091 | AD9: 45419 | AE9: 38229.11 | AF9: =(AE9/AE8)-1 -> -0.00018202708
B10: 45425 | C10: 228.9 | D10: =(C10/C9) -1 -> 0.020053476 | F10: 45425 | G10: 84.8 | H10: =(G10/G9)-1 -> -0.0069094742 | J10: 45425 | K10: 51.42 | L10: =(K10/K9)-1 -> 0.011806375 | N10: 45425 | O10: 6.78 | P10: =(O10/O9)-1 -> 0.010432191 | R10: 45425 | S10: 13.0588 | T10: =(S10/S9)-1 -> -0.0050438095 | V10: 45425 | W10: 52.46 | X10: =(W10/W9)-1 -> 0.006330328 | Z10: 45425 | AA10: 486.69 | AB10: =(AA10/AA9)-1 -> 0.016606091 | AD10: 45425 | AE10: 38787.38 | AF10: =(AE10/AE9)-1 -> 0.01460327
B11: 45432 | C11: 223.9 | D11: =(C11/C10) -1 -> -0.0218436 | F11: 45432 | G11: 84.52 | H11: =(G11/G10)-1 -> -0.0033018868 | J11: 45432 | K11: 47.73 | L11: =(K11/K10)-1 -> -0.07176196 | N11: 45432 | O11: 6.65 | P11: =(O11/O10)-1 -> -0.019174041 | R11: 45432 | S11: 13.4375 | T11: =(S11/S10)-1 -> 0.028999602 | V11: 45432 | W11: 52.29 | X11: =(W11/W10)-1 -> -0.0032405642 | Z11: 45432 | AA11: 486.73 | AB11: =(AA11/AA10)-1 -> 8.218784e-05 | AD11: 45432 | AE11: 38646.11 | AF11: =(AE11/AE10)-1 -> -0.003642164
B12: 45439 | C12: 231.5 | D12: =(C12/C11) -1 -> 0.033943725 | F12: 45439 | G12: 86.24 | H12: =(G12/G11)-1 -> 0.020350213 | J12: 45439 | K12: 47.55 | L12: =(K12/K11)-1 -> -0.0037712131 | N12: 45440 | O12: 7.19 | P12: =(O12/O11)-1 -> 0.081203008 | R12: 45440 | S12: 13.8236 | T12: =(S12/S11)-1 -> 0.028733023 | V12: 45439 | W12: 52.09 | X12: =(W12/W11)-1 -> -0.0038248231 | Z12: 45440 | AA12: 484.62 | AB12: =(AA12/AA11)-1 -> -0.0043350523 | AD12: 45439 | AE12: 38487.9 | AF12: =(AE12/AE11)-1 -> -0.0040938144
B13: 45446 | C13: 231 | D13: =(C13/C12) -1 -> -0.0021598272 | F13: 45446 | G13: 90.4 | H13: =(G13/G12)-1 -> 0.048237477 | J13: 45446 | K13: 47.47 | L13: =(K13/K12)-1 -> -0.0016824395 | N13: 45446 | O13: 6.91 | P13: =(O13/O12)-1 -> -0.038942976 | R13: 45446 | S13: 15.0125 | T13: =(S13/S12)-1 -> 0.086005093 | V13: 45446 | W13: 52.74 | X13: =(W13/W12)-1 -> 0.012478403 | Z13: 45446 | AA13: 490.8 | AB13: =(AA13/AA12)-1 -> 0.01275226 | AD13: 45446 | AE13: 38683.93 | AF13: =(AE13/AE12)-1 -> 0.0050932891
B14: 45453 | C14: 224.9 | D14: =(C14/C13) -1 -> -0.026406926 | F14: 45453 | G14: 87.54 | H14: =(G14/G13)-1 -> -0.031637168 | J14: 45453 | K14: 45.06 | L14: =(K14/K13)-1 -> -0.050768907 | N14: 45453 | O14: 6.68 | P14: =(O14/O13)-1 -> -0.033285094 | R14: 45453 | S14: 14.585 | T14: =(S14/S13)-1 -> -0.02847627 | V14: 45453 | W14: 51.38 | X14: =(W14/W13)-1 -> -0.025786879 | Z14: 45453 | AA14: 498.98 | AB14: =(AA14/AA13)-1 -> 0.016666667 | AD14: 45453 | AE14: 38814.56 | AF14: =(AE14/AE13)-1 -> 0.0033768544
B15: 45460 | C15: 217.8 | D15: =(C15/C14) -1 -> -0.031569586 | F15: 45460 | G15: 89.82 | H15: =(G15/G14)-1 -> 0.026045236 | J15: 45460 | K15: 44.05 | L15: =(K15/K14)-1 -> -0.022414558 | N15: 45460 | O15: 6.99 | P15: =(O15/O14)-1 -> 0.046407186 | R15: 45460 | S15: 15.37 | T15: =(S15/S14)-1 -> 0.05382242 | V15: 45460 | W15: 51.17 | X15: =(W15/W14)-1 -> -0.0040871935 | Z15: 45460 | AA15: 501.78 | AB15: =(AA15/AA14)-1 -> 0.0056114474 | AD15: 45460 | AE15: 38596.47 | AF15: =(AE15/AE14)-1 -> -0.0056187678
B16: 45467 | C16: 223 | D16: =(C16/C15) -1 -> 0.023875115 | F16: 45467 | G16: 70.99 | H16: =(G16/G15)-1 -> -0.20964151 | J16: 45467 | K16: 42.87 | L16: =(K16/K15)-1 -> -0.026787741 | N16: 45467 | O16: 6.67 | P16: =(O16/O15)-1 -> -0.045779685 | R16: 45467 | S16: 15.3 | T16: =(S16/S15)-1 -> -0.0045543266 | V16: 45467 | W16: 50.87 | X16: =(W16/W15)-1 -> -0.0058628102 | Z16: 45467 | AA16: 500.13 | AB16: =(AA16/AA15)-1 -> -0.0032882937 | AD16: 45467 | AE16: 39583.08 | AF16: =(AE16/AE15)-1 -> 0.025562182
... B108: 46111 | C108: 134.9 | D108: =(C108/C107) -1 -> 0.021582734 | F108: 46111 | G108: 37.835 | H108: =(G108/G107)-1 -> -0.15716195 | J108: 46111 | K108: 22.05 | L108: =(K108/K107)-1 -> 0.027014439 | N108: 46111 | O108: 5.62 | P108: =(O108/O107)-1 -> -0.020905923 | R108: 46111 | S108: 27.54 | T108: =(S108/S107)-1 -> 0.053759327 | V108: 46111 | W108: 59.24 | X108: =(W108/W107)-1 -> 0.038387379 | Z108: 46111 | AA108: 602.99 | AB108: =(AA108/AA107)-1 -> 0.034359133 | AD108: 46111 | AE108: 53123.49 | AF108: =(AE108/AE107)-1 -> -0.004676141

Sheet Beta
B2: Company | C2: Beta | D2: Adjusted Beta
B3: Adidas | C3: =SLOPE('Comps Data'!D5:D108,'Comps Data'!X5:X108) -> 1.2557597 | D3: =(C3*$C$9)+(1*$C$10) -> 1.1918198
B4: Puma | C4: =SLOPE('Comps Data'!L5:L108,'Comps Data'!X5:X108) -> 1.4365234 | D4: =(C4*$C$9)+(1*$C$10) -> 1.3273926
B5: Nike | C5: =SLOPE('Comps Data'!H5:H108,'Comps Data'!AB5:AB108) -> 0.75792333 | D5: =(C5*$C$9)+(1*$C$10) -> 0.8184425
B6: Under Armour | C6: =SLOPE('Comps Data'!H6:H109,'Comps Data'!AB6:AB109) -> 0.78467946 | D6: =(C6*$C$9)+(1*$C$10) -> 0.83850959
B7: ASICS | C7: =SLOPE('Comps Data'!T5:T108,'Comps Data'!AF5:AF108) -> 0.95703649 | D7: =(C7*$C$9)+(1*$C$10) -> 0.96777737
B9: Raw Beta Weight | C9: 0.75
B10: Market Beta Weight | C10: 0.25

Sheet Projection
B2: Forecasting
B4: Year Weight | C4: Year | D4: Revenue | E4: Growth | F4: EBIT | G4: Growth | H4: CapEX | I4: Growth | J4: D&A | K4: Growth | L4: NWC | M4: Change NWC
B5: 1 | C5: =BL!$C$10 -> 2021 | D5: {=TRANSPOSE(BL!J13:N13)} -> 21234 | F5: {=TRANSPOSE(BL!J24:N24)} -> 1986 | H5: {=TRANSPOSE(BL!Q26:U26)} -> -667 | J5: {=TRANSPOSE(BL!Q14:U14)} -> 1149 | L5: =D18 -> 1815
B6: 2 | C6: =C5+1 -> 2022 | D6: 22511 | E6: =D6/D5 -1 -> 0.060139399 | F6: 669 | G6: =F6/F5 -1 -> -0.66314199 | H6: -695 | I6: =H6/H5 -1 -> 0.04197901 | J6: 1375 | K6: =J6/J5 - 1 -> 0.19669278 | L6: =D19 -> 2457 | M6: =L6-L5 -> 642
B7: 3 | C7: =C6+1 -> 2023 | D7: 21427 | E7: =D7/D6 -1 -> -0.048154236 | F7: 268 | G7: =F7/F6 -1 -> -0.59940209 | H7: -504 | I7: =H7/H6 -1 -> -0.27482014 | J7: 1212 | K7: =J7/J6 - 1 -> -0.11854545 | L7: =D20 -> 1214 | M7: =L7-L6 -> -1243
B8: 4 | C8: =C7+1 -> 2024 | D8: 23683 | E8: =D8/D7 -1 -> 0.10528772 | F8: 1337 | G8: =F8/F7 -1 -> 3.988806 | H8: -540 | I8: =H8/H7 -1 -> 0.071428571 | J8: 1208 | K8: =J8/J7 - 1 -> -0.00330033 | L8: =D21 -> 508 | M8: =L8-L7 -> -706
B9: 5 | C9: =C8+1 -> 2025 | D9: 24811 | E9: =D9/D8 -1 -> 0.047629101 | F9: 2056 | G9: =F9/F8 -1 -> 0.53777113 | H9: -477 | I9: =H9/H8 -1 -> -0.11666667 | J9: 1154 | K9: =J9/J8 - 1 -> -0.044701987 | L9: =D22 -> 2521 | M9: =L9-L8 -> 2013
B10: 6 | C10: =C9+1 -> 2026 | D10: =_xlfn.FORECAST.ETS(B10,_xlfn.ANCHORARRAY($D$5),$B$5:$B$9) -> 25697.346 | E10: =D10/D9 -1 -> 0.035723909 | F10: =_xlfn.FORECAST.ETS(B10,$F$5:$F$9,$B$5:$B$9) -> 1827.0145 | G10: =F10/F9 -1 -> -0.11137428 | H10: =-(D10*$C$25) -> -604.4459 | I10: =H10/H9 -1 -> 0.26718218 | J10: =_xlfn.FORECAST.ETS(B10,$J$5:$J$9,$B$5:$B$9) -> 1194.4899 | K10: =J10/J9 - 1 -> 0.03508659 | L10: =D10*$E$25 -> 2196.5095 | M10: =L10-L9 -> -324.4905
B11: 7 | C11: =C10+1 -> 2027 | D11: =_xlfn.FORECAST.ETS(B11,_xlfn.ANCHORARRAY($D$5),$B$5:$B$9) -> 26589.895 | E11: =D11/D10 -1 -> 0.034733125 | F11: =_xlfn.FORECAST.ETS(B11,$F$5:$F$9,$B$5:$B$9) -> 1964.2099 | G11: =F11/F10 -1 -> 0.07509271 | H11: =-(D11*$C$25) -> -625.4402 | I11: =H11/H10 -1 -> 0.034733125 | J11: =_xlfn.FORECAST.ETS(B11,$J$5:$J$9,$B$5:$B$9) -> 981.40643 | K11: =J11/J10 - 1 -> -0.17838869 | L11: =D11*$E$25 -> 2272.8011 | M11: =L11-L10 -> 76.291639
B12: 8 | C12: =C11+1 -> 2028 | D12: =_xlfn.FORECAST.ETS(B12,_xlfn.ANCHORARRAY($D$5),$B$5:$B$9) -> 27482.444 | E12: =D12/D11 -1 -> 0.03356723 | F12: =_xlfn.FORECAST.ETS(B12,$F$5:$F$9,$B$5:$B$9) -> 2101.4054 | G12: =F12/F11 -1 -> 0.06984766 | H12: =-(D12*$C$25) -> -646.43449 | I12: =H12/H11 -1 -> 0.03356723 | J12: =_xlfn.FORECAST.ETS(B12,$J$5:$J$9,$B$5:$B$9) -> 1114.5511 | K12: =J12/J11 - 1 -> 0.13566719 | L12: =D12*$E$25 -> 2349.0928 | M12: =L12-L11 -> 76.291639
B13: 9 | C13: =C12+1 -> 2029 | D13: =_xlfn.FORECAST.ETS(B13,_xlfn.ANCHORARRAY($D$5),$B$5:$B$9) -> 28374.993 | E13: =D13/D12 -1 -> 0.032477065 | F13: =_xlfn.FORECAST.ETS(B13,$F$5:$F$9,$B$5:$B$9) -> 2238.6009 | G13: =F13/F12 -1 -> 0.065287482 | H13: =-(D13*$C$25) -> -667.42879 | I13: =H13/H12 -1 -> 0.032477065 | J13: =_xlfn.FORECAST.ETS(B13,$J$5:$J$9,$B$5:$B$9) -> 901.46758 | K13: =J13/J12 - 1 -> -0.19118325 | L13: =D13*$E$25 -> 2425.3844 | M13: =L13-L12 -> 76.291639
B14: 10 | C14: =C13+1 -> 2030 | D14: =_xlfn.FORECAST.ETS(B14,_xlfn.ANCHORARRAY($D$5),$B$5:$B$9) -> 29267.542 | E14: =D14/D13 -1 -> 0.031455483 | F14: =_xlfn.FORECAST.ETS(B14,$F$5:$F$9,$B$5:$B$9) -> 2375.7963 | G14: =F14/F13 -1 -> 0.061286257 | H14: =-(D14*$C$25) -> -688.42308 | I14: =H14/H13 -1 -> 0.031455483 | J14: =_xlfn.FORECAST.ETS(B14,$J$5:$J$9,$B$5:$B$9) -> 1034.6122 | K14: =J14/J13 - 1 -> 0.14769766 | L14: =D14*$E$25 -> 2501.6761 | M14: =L14-L13 -> 76.291639
B17: Year | C17: CapEX%Sales | D17: NWC | E17: NWC%Sales | F17: D&A%Sales
B18: =C5 -> 2021 | C18: =ABS(BL!Q26)/BL!J13 -> 0.031411887 | D18: =(BL!C15+BL!C17+BL!C20+BL!C19)-(BL!C38+BL!C43+BL!C44+BL!C42+BL!C45) -> 1815 | E18: =D18/BL!J13 -> 0.085476123 | F18: =BL!Q$14/BL!J$13 -> 0.054111331
B19: =C6 -> 2022 | C19: =ABS(BL!R26)/BL!K13 -> 0.030873795 | D19: =(SUM(BL!D15,BL!D17,BL!D19,BL!D20)-(SUM(BL!D38,BL!D42,BL!D43,BL!D45,BL!D44))) -> 2457 | E19: =D19/BL!K13 -> 0.10914664 | F19: =BL!R14/BL!K13 -> 0.061081249 | N19: n
B20: =C7 -> 2023 | C20: =ABS(BL!S26)/BL!L13 -> 0.023521725 | D20: =(SUM(BL!E15,BL!E17,BL!E19,BL!E20)-(SUM(BL!E38,BL!E42,BL!E43,BL!E45,BL!E44))) -> 1214 | E20: =D20/BL!L13 -> 0.056657488 | F20: =BL!S14/BL!L13 -> 0.056564148
B21: =C8 -> 2024 | C21: =ABS(BL!T26)/BL!M13 -> 0.022801165 | D21: =(BL!F15+BL!F17+BL!F19+BL!F20)-(BL!F38+BL!F42+BL!F43+BL!F45+BL!F44) -> 508 | E21: =(ABS(D21)/BL!M13) -> 0.021449985 | F21: =BL!T14/BL!M13 -> 0.051007051
B22: =C9 -> 2025 | C22: =ABS(BL!U26)/BL!N13 -> 0.019225344 | D22: =(BL!G15+BL!G17+BL!G19+BL!G20)-(BL!G38+BL!G42+BL!G43+BL!G45+BL!G44) -> 2521 | E22: =D22/BL!N13 -> 0.10160816 | F22: =BL!U14/BL!N13 -> 0.046511628
B24: Average | C24: =AVERAGE(C18:C22) -> 0.025566783 | D24: =AVERAGE(D18:D22) -> 1703 | E24: =AVERAGE(E18:E22) -> 0.074867679 | F24: =AVERAGE(F18:F22) -> 0.053855081
B25: Median | C25: =MEDIAN(C18:C22) -> 0.023521725 | D25: =MEDIAN(D18:D22) -> 1815 | E25: =MEDIAN(E18:E22) -> 0.085476123 | F25: =MEDIAN(F18:F22) -> 0.054111331

Sheet WACC
C2: Weighted Avg Cost of Capital
B7: Peers Comp
B9: Brand | C9: Country | D9: Total Debt(in millions) | E9: Market Cap(in millions) | F9: Tax rate | G9: D/E | H9: D/Capital | I9: Levered Beta 2 | J9: Unlevered Beta 3
B10: Adidas | C10: Germany | D10: =BL!G37+BL!G39+BL!G48+BL!G49 -> 5554 | E10: =180*136.9 -> 24642 | F10: 0.3 | G10: =D10/E10 -> 0.22538755 | H10: =D10/(D10+E10) -> 0.18393165 | I10: =Beta!D3 -> 1.1918198 | J10: =I10/((1+(1-F10)*G10)) -> 1.0294086
B11: Nike | C11: USA | D11: 11018 | E11: =1476*44.63 -> 65873.88 | F11: 0.25 | G11: =D11/E11 -> 0.16725901 | H11: =D11/(D11+E11) -> 0.14329211 | I11: =Beta!D4 -> 1.3273926 | J11: =I11/((1+(1-F11)*G11)) -> 1.1794387
B12: Puma | C12: Germany | D12: 2582.3 | E12: =147.21*22.91 -> 3372.5811 | F12: 0.3 | G12: =D12/E12 -> 0.76567469 | H12: =D12/(D12+E12) -> 0.43364426 | I12: =Beta!D5 -> 0.8184425 | J12: =I12/((1+(1-F12)*G12)) -> 0.53284978
B13: Under Armour | C13: USA | D13: 1299.452 | E13: 2385.56 | F13: 0.25 | G13: =D13/E13 -> 0.54471571 | H13: =D13/(D13+E13) -> 0.35263169 | I13: =Beta!D6 -> 0.83850959 | J13: =I13/((1+(1-F13)*G13)) -> 0.59530543
B14: ASICS | C14: Japan | D14: 98529 | E14: =734.48294*4353 -> 3197204.2 | F14: 0.31 | G14: =D14/E14 -> 0.030817237 | H14: =D14/(D14+E14) -> 0.029895927 | I14: =Beta!D7 -> 0.96777737 | J14: =I14/((1+(1-F14)*G14)) -> 0.94762713
E16: Average | F16: =AVERAGE(F10:F14) -> 0.282 | G16: =AVERAGE(G10:G14) -> 0.34677084 | H16: =AVERAGE(H10:H14) -> 0.22867913 | I16: =AVERAGE(I10:I14) -> 1.0287884 | J16: =AVERAGE(J10:J14) -> 0.85692594
E17: Median | F17: =MEDIAN(F10:F14) -> 0.3 | G17: =MEDIAN(G10:G14) -> 0.22538755 | H17: =MEDIAN(H10:H14) -> 0.18393165 | I17: =MEDIAN(I10:I14) -> 0.96777737 | J17: =MEDIAN(J10:J14) -> 0.94762713
B20: Cost of Debt | E20: Cost of Equity | I20: Weighted Avg Cost of Capital
B22: Country's Rfr | C22: 0.03 | E22: Risk Free rate | F22: =C22 -> 0.03 | J22: Total Cost | K22: Total Weight
B23: Interest Coverage Ratio | C23: =BL!N24/BL!N26 -> 6.6322581 | E23: Equity Risk Premium | F23: 0.0423 | I23: Debt | J23: =C27 -> 0.0259 | K23: =C35 -> 0.18393165
B24: Defualt spread( Damodaran table) | C24: 0.007 | E24: Market Return | F24: =F22+F23 -> 0.0723 | I24: Equity | J24: =F26 -> 0.076408831 | K24: =C36 -> 0.81606835
B25: Pre Tax cost of debt | C25: =C22+C24 -> 0.037 | E25: Levered Beta | F25: =F34 -> 1.0971355 | I25: WACC | K25: =SUMPRODUCT(J23:J24,K23:K24) -> 0.067118658
B26: Tax Rate | C26: =F10 -> 0.3 | E26: Cost of Equity | F26: =F22+F25*(F24-F22) -> 0.076408831
B27: Post Tax Cost of Debt | C27: =C25*(1-C26) -> 0.0259
B29: Capital Structure | E29: Levered Beta
B31: Total Debt | C31: =D10 -> 5554 | E31: Comps Median Unlevered Beta | F31: =J17 -> 0.94762713
B32: Total Equity(MC) | C32: =E10 -> 24642 | E32: D/E | F32: =G10 -> 0.22538755
B33: V | C33: =C31+C32 -> 30196 | E33: Tax Rate | F33: =F10 -> 0.3
E34: Levered Beta | F34: =F31*(1+(1-F33)*F32) -> 1.0971355
B35: D/V | C35: =C31/C33 -> 0.18393165
B36: E/V | C36: =C32/C33 -> 0.81606835

Sheet DCF
C2: Adidas 5-Year Unlevered DCF for Projected 2026-2030
B8: Assumptions | F8: DCF
B9: Tax Rate | C9: =WACC!F10 -> 0.3 | F9: Year | G9: 2025 | H9: 2026 | I9: 2027 | J9: 2028 | K9: 2029 | L9: 2030
B10: Discount Rate | C10: =WACC!K25 -> 0.067118658 | G10: 0 | H10: 1 | I10: 2 | J10: 3 | K10: 4 | L10: 5
B11: Pepretual Growth Rate | C11: 0.02 | F11: EBIT | G11: =Projection!F9 -> 2056 | H11: {=TRANSPOSE(Projection!F10:F14)} -> 1827.0145 | I11: 1964.2099 | J11: 2101.4054 | K11: 2238.6009 | L11: 2375.7963
B12: Current Price | C12: 134.9 | F12: Tax Rate | G12: =$C$9 -> 0.3 | H12: =$C$9 -> 0.3 | I12: =$C$9 -> 0.3 | J12: =$C$9 -> 0.3 | K12: =$C$9 -> 0.3 | L12: =$C$9 -> 0.3
B13: Shares Outstanding(in thousands) | C13: 180000 | F13: D&A | G13: =Projection!J9 -> 1154 | H13: {=TRANSPOSE(Projection!J10:J14)} -> 1194.4899 | I13: 981.40643 | J13: 1114.5511 | K13: 901.46758 | L13: 1034.6122
B14: Debt(in millions) | C14: =WACC!D10 -> 5554 | F14: CapEx | G14: =Projection!H9 -> -477 | H14: {=TRANSPOSE(Projection!H10:H14)} -> -604.4459 | I14: -625.4402 | J14: -646.43449 | K14: -667.42879 | L14: -688.42308
B15: Cash&Cash equivalents(in millions) | C15: =BL!G13 -> 1617 | F15: Change in NWC | G15: =Projection!M9 -> 2013 | H15: {=TRANSPOSE(Projection!M10:M14)} -> -324.4905 | I15: 76.291639 | J15: 76.291639 | K15: 76.291639 | L15: 76.291639
F16: FCF | G16: =G11*(1-G12)+G13+G14-G15 -> 103.2 | H16: =H11*(1-H12)+H13+H14-H15 -> 2193.4446 | I16: =I11*(1-I12)+I13+I14-I15 -> 1654.6215 | J16: =J11*(1-J12)+J13+J14-J15 -> 1862.8087 | K16: =K11*(1-K12)+K13+K14-K15 -> 1724.7678 | L16: =L11*(1-L12)+L13+L14-L15 -> 1932.9549
F18: Enterprice Value | I18: Equity Value | L18: Impled Price per Share | N18: =J23*1000000/(C13*1000) -> 189.27939
F20: Terminal Value | G20: =((L16*(1+C11))/(C10-C11)) -> 41843.595 | I20: Enterpice Value | J20: =G23 -> 38007.29 | L20: Stock is Undervalued
F21: PV of TV | G21: =-PV(C10,5,0,G20) -> 30238.86 | I21: Add: Cash&equivalents(in millions) | J21: =C15 -> 1617
F22: PV of FCFs | G22: =NPV(C10,H16:L16) -> 7768.4296 | I22: Less: Debt(in millions) | J22: =C14 -> 5554
F23: Enterprice Value | G23: =G21+G22 -> 38007.29 | I23: Equity Value | J23: =J20+J21-J22 -> 34070.29

Sheet LBO
C2: Weighted Avg Cost of Capital
B7: Standard LBO Model
B8: (in millions euros)
C10: Step 1.Model Assumptions
B12: Entry Valuation | E12: Transaction Asssumptions
B13: LTM EBITDA | C13: =BL!N22 -> 3210 | E13: Transaction Fees | H13: 411.39
B14: Entry Multiple | C14: 9 | E14: Cash to B/S | H14: 500
B15: Purchase Enteprice Value | C15: =C13*C14 -> 28890 | E15: Rollover Equity | H15: 0.15
E16: Financing Fees Amortization Period(years) | H16: 5
E17: Tax Rate | H17: 0.3
E19: Curcularity Toggle (0=off, 1=on) | H19: 1
B21: Debt Assumptions
B22: Tranche | C22: X EBITDA | D22: X Amount | E22: Rate(E +) | F22: Floor | G22: %Amort | H22: %Fee | I22: %Fee
B23: Revolver | C23: 0 | D23: - | E23: =C29 + 350 -> 570 | F23: 0 | G23: - | H23: - | I23: -
B24: Term Loan B | C24: 4.5 | D24: =C24*$C$13 -> 14445 | E24: =C29 + 350 -> 570 | F24: 0.005 | G24: 0.01 | H24: 0.025 | I24: =D24*H24 -> 361.125
B25: Senior Notes | C25: 1 | D25: =C25*$C$13 -> 3210 | E25: 0.07 | F25: - | G25: - | H25: 0.025 | I25: =D25*H25 -> 80.25
B26: Subordinated Notes | C26: 0.5 | D26: =C26*$C$13 -> 1605 | E26: 0.11 | F26: - | G26: - | H26: 0.025 | I26: =D26*H26 -> 40.125
B27: Total Debt | C27: =SUM(C23:C26) -> 6 | D27: =SUM(D23:D26) -> 19260 | I27: =SUM(I23:I26) -> 481.5
B29: E - Euribor | C29: 220
C31: Step 2. Sources and Uses Table
B33: Sources ans Uses
B34: Sources | D34: Amount | F34: Uses | I34: Amount
B35: Revolver | D35: - | F35: Purchase Enterpice Value | I35: =C15 -> 28890
B36: Term Loan B | D36: =D24 -> 14445 | F36: Cash to B/S | I36: =H14 -> 500
B37: Senior Notes | D37: =D25 -> 3210 | F37: Transaction Fees | I37: =H13 -> 411.39
B38: Subordinated Notes | D38: =D26 -> 1605 | F38: Financing Fees | I38: =I27 -> 481.5
B39: Total Debt | D39: =SUM(D35:D38) -> 19260 | F39: Total Uses | I39: =SUM(I35:I38) -> 30282.89
B40: Rollover Equity | D40: =D42*H15 -> 1653.4335
B41: Sponsor Equity | D41: =D42-D40 -> 9369.4565
B42: Total Equity | D42: =I39-D39 -> 11022.89
B44: Total Sources | D44: =D39+D42 -> 30282.89 | F44: Check | I44: =I39-D44 -> 0
C46: Step 3. Purchase Price Allocation
B48: GoodWill Calculation | F48: Intangible Assets Write-up
B49: Purchase Enterprice Value | C49: =C15 -> 28890 | F49: Intangible Assets Allocation | H49: 0.2
B50: Cash | C50: =BL!G13 -> 1617 | F50: Useful Life Assumption | H50: 15
B51: Debt | C51: =BL!G37+BL!G39+BL!G48+BL!G49 -> 5554 | F51: Annual Amortization | H51: =C56/H50 -> 271.73333
B52: Purchase Equity Value | C52: =C49+C50-C51 -> 24953 | F52: Defered Tax Liability | H52: =C56*H17 -> 1222.8
B53: Book Value of Equity | C53: =BL!G62 -> 5776 | F53: Annual Unwind of DTL | H53: =H52/H50 -> 81.52
B54: Existing Goodwill | C54: =BL!G25 -> 1203
B55: Allocable Purchase Premium | C55: =C52-C53+C54 -> 20380 | F55: PP&E Write-up
...
